<?xml version="1.0"?>
<robot xmlns:xacro="http://www.ros.org/wiki/xacro" name="myCameraStereo">  
  
  <link name="world"/>

  <joint name="fixed_joint" type="revolute">
    <limit upper="0" lower="0" effort="1000000000" velocity="0" />
    <origin xyz="0 0 0" rpy="0 0 0"/>
    <axis xyz="0 0 1" />
    <parent link="world" />
    <child link="second_link" />
  </joint>
  
  <!-- Sensor link -->
  <link name="cameras">
    <inertial>
      <origin xyz="0 0 0" rpy="0 0 0"/>
      <mass value="0.1"/>
      <inertia ixx="0.4" ixy="0.0" ixz="0.0" iyy="0.4" iyz="0.0" izz="0.2"/>
    </inertial>

    <visual>
      <origin xyz="0 0 0" rpy="0 0 0"/>
      <geometry>
        <mesh filename="file://$(find camera_stereo)/meshes/ZEDM.stl" scale="1 1 1"/>
      </geometry>
    </visual>

    <collision>
      <geometry>
       <box size="0.05 0.05 0.05"/>
      </geometry>
      <origin xyz="0 0 0" rpy="0 0 0"/>
    </collision>
  </link>

  <link name="second_link">
    <inertial>
        <mass value="1000" />
        <inertia ixx="100" ixy="0.0" ixz="0.0" iyy="100" iyz="0.0" izz="100"/>
    </inertial>
    <origin rpy="0.0 0.0 0.0" xyz="0.0 0.0 0.0" />
    <collision>
      <geometry>
        <box size="0.005 0.005 0.015" />
      </geometry>
    </collision>
    <visual>
      <geometry>
        <box size="0.05 0.05 0.15" />
      </geometry>
    </visual>
  </link>

  <joint name="base_to_second_joint" type="prismatic">
    <parent link="second_link"/>
    <child link="cameras"/>
    <axis xyz="1 0 0" />
    <limit upper="5" lower="-1" effort="10000" velocity="1"/>
    <origin xyz="0.3 0. 0" rpy="0.0 0.0 0.0"/> 
  </joint>

  <!-- camera -->
  <gazebo reference="cameras">
    <sensor type="multicamera" name="stereo_camera">
      <update_rate>30</update_rate>

        <camera name="left">
          <horizontal_fov>1.3962634</horizontal_fov>
          <image>
            <width>640</width>
            <height>480</height>
            <format>R8G8B8</format>
          </image>
          <clip>
            <near>0.02</near>
            <far>300</far>
          </clip>
          <noise>
            <type>gaussian</type>
            <mean>0.0</mean>
            <stddev>0.007</stddev>
          </noise>
        </camera>
        <camera name="right">
          <pose>0 -0.10 0 0 0 0</pose>
          <horizontal_fov>1.3962634</horizontal_fov>
          <image>
            <width>640</width>
            <height>480</height>
            <format>R8G8B8</format>
          </image>
          <clip>
            <near>0.02</near>
            <far>300</far>
          </clip>
          <noise>
            <type>gaussian</type>
            <mean>0.0</mean>
            <stddev>0.007</stddev>
          </noise>
        </camera>

      <plugin name="camera_controller" filename="libgazebo_ros_multicamera.so">
        <updateRate>0.0</updateRate>
        <scale_to_hfov>true</scale_to_hfov>
        <alwaysOn>true</alwaysOn>
        <baseline>0.12</baseline>
        <frameName>cameras</frameName>
        <cameraName>myCameraStereo/stereo_camera</cameraName>
        <cameraInfoTopicName>camera_info</cameraInfoTopicName>        

        <hackBaseline>0.07</hackBaseline>
        <focal_length>320</focal_length>
        <distortion_k1>0.00000001</distortion_k1>
        <distortion_k2>0.00000001</distortion_k2>
        <distortion_k3>0.00000001</distortion_k3>
        <distortion_t1>0.00000001</distortion_t1>
        <distortion_t2>0.00000001</distortion_t2>

        <!-- required for ros depth cam -->
        <imageTopicName>image_raw</imageTopicName>
        <pointCloudTopicName>camera_cloud</pointCloudTopicName>
        <depthImageTopicName>camera_depth</depthImageTopicName>
        <depthImageCameraInfoTopicName>depth_info</depthImageCameraInfoTopicName>
      </plugin>

    </sensor>
  </gazebo>

    <!-- ROS Control plugin for Gazebo -->
  <gazebo>
    <plugin name="gazebo_ros_control" filename="libgazebo_ros_control.so">
      <robotNamespace>/rrbot</robotNamespace>
    </plugin>
  </gazebo>

  <!-- transmission -->
  <transmission name="base_to_second_trans">
    <type>transmission_interface/SimpleTransmission</type>
    <actuator name="motor1">
      <mechanicalReduction>1</mechanicalReduction>
    </actuator>
    <joint name="base_to_second_joint">
      <hardwareInterface>hardware_interface/PositionJointInterface</hardwareInterface>
    </joint>
  </transmission>

</robot>